{
  "dataType": "CVE_RECORD",
  "containers": {
    "cna": {
      "title": "Groups not dropped before running subprocess when using empty 'extra_groups' parameter",
      "source": {
        "discovery": "UNKNOWN"
      },
      "impacts": [
        {
          "capecId": "CAPEC-122",
          "descriptions": [
            {
              "lang": "en",
              "value": "CAPEC-122 Privilege Abuse"
            }
          ]
        }
      ],
      "metrics": [
        {
          "format": "CVSS",
          "cvssV3_1": {
            "scope": "UNCHANGED",
            "version": "3.1",
            "baseScore": 6.1,
            "attackVector": "ADJACENT_NETWORK",
            "baseSeverity": "MEDIUM",
            "vectorString": "CVSS:3.1/AV:A/AC:L/PR:H/UI:N/S:U/C:H/I:H/A:N",
            "integrityImpact": "HIGH",
            "userInteraction": "NONE",
            "attackComplexity": "LOW",
            "availabilityImpact": "NONE",
            "privilegesRequired": "HIGH",
            "confidentialityImpact": "HIGH"
          },
          "scenarios": [
            {
              "lang": "en",
              "value": "GENERAL"
            }
          ]
        }
      ],
      "affected": [
        {
          "repo": "https://github.com/python/cpython",
          "vendor": "Python Software Foundation",
          "product": "CPython",
          "versions": [
            {
              "status": "affected",
              "version": "3.12.0",
              "lessThan": "3.12.1",
              "versionType": "python"
            },
            {
              "status": "affected",
              "version": "3.13.0a1",
              "lessThan": "3.13.0a3",
              "versionType": "python"
            }
          ],
          "platforms": [
            "POSIX"
          ],
          "defaultStatus": "unaffected"
        }
      ],
      "references": [
        {
          "url": "https://github.com/python/cpython/issues/112334",
          "tags": [
            "issue-tracking"
          ]
        },
        {
          "url": "https://mail.python.org/archives/list/security-announce@python.org/thread/AUL7QFHBLILGISS7U63B47AYSSGJJQZD/",
          "tags": [
            "vendor-advisory"
          ]
        },
        {
          "url": "https://github.com/python/cpython/commit/9fe7655c6ce0b8e9adc229daf681b6d30e6b1610",
          "tags": [
            "patch"
          ]
        },
        {
          "url": "https://github.com/python/cpython/commit/10e9bb13b8dcaa414645b9bd10718d8f7179e82b",
          "tags": [
            "patch"
          ]
        },
        {
          "url": "https://github.com/python/cpython/commit/85bbfa8a4bbdbb61a3a84fbd7cb29a4096ab8a06",
          "tags": [
            "patch"
          ]
        }
      ],
      "x_generator": {
        "engine": "Vulnogram 0.1.0-dev"
      },
      "descriptions": [
        {
          "lang": "en",
          "value": "An issue was found in CPython 3.12.0 `subprocess` module on POSIX platforms. The issue was fixed in CPython 3.12.1 and does not affect other stable releases.\n\nWhen using the `extra_groups=` parameter with an empty list as a value (ie `extra_groups=[]`) the logic regressed to not call `setgroups(0, NULL)` before calling `exec()`, thus not dropping the original processes' groups before starting the new process. There is no issue when the parameter isn't used or when any value is used besides an empty list.\n\nThis issue only impacts CPython processes run with sufficient privilege to make the `setgroups` system call (typically `root`).\n\n",
          "supportingMedia": [
            {
              "type": "text/html",
              "value": "<p><span style=\"background-color: transparent;\">An issue was found in CPython 3.12.0 `subprocess` module on POSIX platforms. The issue was fixed in CPython 3.12.1 and does not affect other stable releases.</span></p><p><span style=\"background-color: transparent;\">When using the `extra_groups=` parameter with an empty list as a value (ie `extra_groups=[]`) the logic regressed to not call `setgroups(0, NULL)` before calling `exec()`, thus not dropping the original processes' groups before starting the new process. There is no issue when the parameter isn't used or when any value is used besides an empty list.</span></p><p><span style=\"background-color: transparent;\">This issue only impacts CPython processes run with sufficient privilege to make the `setgroups` system call (typically `root`).</span></p>",
              "base64": false
            }
          ]
        }
      ],
      "problemTypes": [
        {
          "descriptions": [
            {
              "lang": "en",
              "type": "CWE",
              "cweId": "CWE-269",
              "description": "CWE-269 Improper Privilege Management"
            }
          ]
        }
      ],
      "providerMetadata": {
        "orgId": "28c92f92-d60d-412d-b760-e73465c3df22",
        "shortName": "PSF",
        "dateUpdated": "2024-05-07T21:36:25.215Z"
      }
    },
    "adp": [
      {
        "metrics": [
          {
            "other": {
              "type": "ssvc",
              "content": {
                "id": "CVE-2023-6507",
                "role": "CISA Coordinator",
                "options": [
                  {
                    "Exploitation": "none"
                  },
                  {
                    "Automatable": "no"
                  },
                  {
                    "Technical Impact": "total"
                  }
                ],
                "version": "2.0.3",
                "timestamp": "2024-01-31T20:16:20.207522Z"
              }
            }
          }
        ],
        "affected": [
          {
            "cpes": [
              "cpe:2.3:a:python:cpython:3.13.0:*:*:*:*:*:*:*"
            ],
            "vendor": "python",
            "product": "cpython",
            "versions": [
              {
                "status": "affected",
                "version": "3.13.0"
              }
            ],
            "defaultStatus": "unknown"
          },
          {
            "cpes": [
              "cpe:2.3:a:python:cpython:*:*:*:*:*:*:*:*"
            ],
            "vendor": "python",
            "product": "cpython",
            "versions": [
              {
                "status": "affected",
                "version": "3.12.0"
              }
            ],
            "defaultStatus": "unknown"
          }
        ],
        "providerMetadata": {
          "shortName": "CISA-ADP",
          "orgId": "134c704f-9b21-4f2e-91b3-4a467353bcc0",
          "dateUpdated": "2024-05-08T15:05:49.608Z"
        }
      }
    ]
  },
  "cveMetadata": {
    "cveId": "CVE-2023-6507",
    "state": "PUBLISHED",
    "dateUpdated": "2024-05-07T21:36:25.215Z",
    "dateReserved": "2023-12-04T21:24:50.284Z",
    "assignerOrgId": "28c92f92-d60d-412d-b760-e73465c3df22",
    "datePublished": "2023-12-08T18:20:49.583Z",
    "assignerShortName": "PSF"
  },
  "dataVersion": "5.0"
}